2020-09-07 15:01:30,790 ERROR: Exception on /representative/2204 [GET] [in /Users/michellewong/Documents/Speakup/venv/lib/python3.7/site-packages/flask/app.py:1892]
Traceback (most recent call last):
  File "/Users/michellewong/Documents/Speakup/venv/lib/python3.7/site-packages/flask/app.py", line 2447, in wsgi_app
    response = self.full_dispatch_request()
  File "/Users/michellewong/Documents/Speakup/venv/lib/python3.7/site-packages/flask/app.py", line 1952, in full_dispatch_request
    rv = self.handle_user_exception(e)
  File "/Users/michellewong/Documents/Speakup/venv/lib/python3.7/site-packages/flask/app.py", line 1821, in handle_user_exception
    reraise(exc_type, exc_value, tb)
  File "/Users/michellewong/Documents/Speakup/venv/lib/python3.7/site-packages/flask/_compat.py", line 39, in reraise
    raise value
  File "/Users/michellewong/Documents/Speakup/venv/lib/python3.7/site-packages/flask/app.py", line 1950, in full_dispatch_request
    rv = self.dispatch_request()
  File "/Users/michellewong/Documents/Speakup/venv/lib/python3.7/site-packages/flask/app.py", line 1936, in dispatch_request
    return self.view_functions[rule.endpoint](**req.view_args)
  File "/Users/michellewong/Documents/Speakup/venv/lib/python3.7/site-packages/flask_login/utils.py", line 272, in decorated_view
    return func(*args, **kwargs)
  File "/Users/michellewong/Documents/Speakup/app/routes.py", line 206, in postcode
    return render_template('test.html', reps=people)
  File "/Users/michellewong/Documents/Speakup/venv/lib/python3.7/site-packages/flask/templating.py", line 138, in render_template
    ctx.app.jinja_env.get_or_select_template(template_name_or_list),
  File "/Users/michellewong/Documents/Speakup/venv/lib/python3.7/site-packages/jinja2/environment.py", line 930, in get_or_select_template
    return self.get_template(template_name_or_list, parent, globals)
  File "/Users/michellewong/Documents/Speakup/venv/lib/python3.7/site-packages/jinja2/environment.py", line 883, in get_template
    return self._load_template(name, self.make_globals(globals))
  File "/Users/michellewong/Documents/Speakup/venv/lib/python3.7/site-packages/jinja2/environment.py", line 857, in _load_template
    template = self.loader.load(self, name, globals)
  File "/Users/michellewong/Documents/Speakup/venv/lib/python3.7/site-packages/jinja2/loaders.py", line 127, in load
    code = environment.compile(source, name, filename)
  File "/Users/michellewong/Documents/Speakup/venv/lib/python3.7/site-packages/jinja2/environment.py", line 638, in compile
    self.handle_exception(source=source_hint)
  File "/Users/michellewong/Documents/Speakup/venv/lib/python3.7/site-packages/jinja2/environment.py", line 832, in handle_exception
    reraise(*rewrite_traceback_stack(source=source))
  File "/Users/michellewong/Documents/Speakup/venv/lib/python3.7/site-packages/jinja2/_compat.py", line 28, in reraise
    raise value.with_traceback(tb)
  File "/Users/michellewong/Documents/Speakup/app/templates/test.html", line 3, in template
    {% block content %}
jinja2.exceptions.TemplateSyntaxError: Unexpected end of template. Jinja was looking for the following tags: 'endblock'. The innermost block that needs to be closed is 'block'.
2020-09-07 15:01:47,870 INFO: Microblog startup [in /Users/michellewong/Documents/Speakup/app/__init__.py:50]
2020-09-07 15:02:30,124 INFO: Microblog startup [in /Users/michellewong/Documents/Speakup/app/__init__.py:50]
2020-09-07 15:06:42,456 INFO: Microblog startup [in /Users/michellewong/Documents/Speakup/app/__init__.py:50]
2020-09-07 15:08:10,483 INFO: Microblog startup [in /Users/michellewong/Documents/Speakup/app/__init__.py:50]
2020-09-07 15:09:10,154 INFO: Microblog startup [in /Users/michellewong/Documents/Speakup/app/__init__.py:50]
2020-09-07 15:09:45,668 ERROR: Exception on /hansard [GET] [in /Users/michellewong/Documents/Speakup/venv/lib/python3.7/site-packages/flask/app.py:1892]
Traceback (most recent call last):
  File "/Users/michellewong/Documents/Speakup/venv/lib/python3.7/site-packages/flask/app.py", line 2447, in wsgi_app
    response = self.full_dispatch_request()
  File "/Users/michellewong/Documents/Speakup/venv/lib/python3.7/site-packages/flask/app.py", line 1952, in full_dispatch_request
    rv = self.handle_user_exception(e)
  File "/Users/michellewong/Documents/Speakup/venv/lib/python3.7/site-packages/flask/app.py", line 1821, in handle_user_exception
    reraise(exc_type, exc_value, tb)
  File "/Users/michellewong/Documents/Speakup/venv/lib/python3.7/site-packages/flask/_compat.py", line 39, in reraise
    raise value
  File "/Users/michellewong/Documents/Speakup/venv/lib/python3.7/site-packages/flask/app.py", line 1950, in full_dispatch_request
    rv = self.dispatch_request()
  File "/Users/michellewong/Documents/Speakup/venv/lib/python3.7/site-packages/flask/app.py", line 1936, in dispatch_request
    return self.view_functions[rule.endpoint](**req.view_args)
  File "/Users/michellewong/Documents/Speakup/venv/lib/python3.7/site-packages/flask_login/utils.py", line 272, in decorated_view
    return func(*args, **kwargs)
  File "/Users/michellewong/Documents/Speakup/app/routes.py", line 234, in main
    obj = Hansard.query.order_by(Hansard.date.desc()).first().date
AttributeError: 'NoneType' object has no attribute 'date'
2020-09-07 15:10:16,274 INFO: Microblog startup [in /Users/michellewong/Documents/Speakup/app/__init__.py:50]
2020-09-07 15:10:39,296 INFO: Microblog startup [in /Users/michellewong/Documents/Speakup/app/__init__.py:50]
2020-09-07 15:25:07,643 INFO: Microblog startup [in /Users/michellewong/Documents/Speakup/app/__init__.py:54]
2020-09-07 16:06:54,541 INFO: Microblog startup [in /Users/michellewong/Documents/Speakup/app/__init__.py:54]
2020-09-07 16:07:21,291 INFO: Microblog startup [in /Users/michellewong/Documents/Speakup/app/__init__.py:54]
2020-09-07 16:07:29,721 INFO: Microblog startup [in /Users/michellewong/Documents/Speakup/app/__init__.py:54]
2020-09-07 16:10:05,735 INFO: Microblog startup [in /Users/michellewong/Documents/Speakup/app/__init__.py:54]
2020-09-07 16:17:49,755 INFO: Microblog startup [in /Users/michellewong/Documents/Speakup/app/__init__.py:54]
2020-09-07 16:18:13,131 ERROR: Exception on /reset_password_request [GET] [in /Users/michellewong/Documents/Speakup/venv/lib/python3.7/site-packages/flask/app.py:1892]
Traceback (most recent call last):
  File "/Users/michellewong/Documents/Speakup/venv/lib/python3.7/site-packages/flask/app.py", line 2447, in wsgi_app
    response = self.full_dispatch_request()
  File "/Users/michellewong/Documents/Speakup/venv/lib/python3.7/site-packages/flask/app.py", line 1952, in full_dispatch_request
    rv = self.handle_user_exception(e)
  File "/Users/michellewong/Documents/Speakup/venv/lib/python3.7/site-packages/flask/app.py", line 1821, in handle_user_exception
    reraise(exc_type, exc_value, tb)
  File "/Users/michellewong/Documents/Speakup/venv/lib/python3.7/site-packages/flask/_compat.py", line 39, in reraise
    raise value
  File "/Users/michellewong/Documents/Speakup/venv/lib/python3.7/site-packages/flask/app.py", line 1950, in full_dispatch_request
    rv = self.dispatch_request()
  File "/Users/michellewong/Documents/Speakup/venv/lib/python3.7/site-packages/flask/app.py", line 1936, in dispatch_request
    return self.view_functions[rule.endpoint](**req.view_args)
  File "/Users/michellewong/Documents/Speakup/app/routes.py", line 271, in reset_password_request
    form = ResetPasswordRequestForm()
NameError: name 'ResetPasswordRequestForm' is not defined
2020-09-07 16:19:49,891 INFO: Microblog startup [in /Users/michellewong/Documents/Speakup/app/__init__.py:54]
2020-09-07 16:19:56,212 ERROR: Exception on /reset_password_request [POST] [in /Users/michellewong/Documents/Speakup/venv/lib/python3.7/site-packages/flask/app.py:1892]
Traceback (most recent call last):
  File "/Users/michellewong/Documents/Speakup/venv/lib/python3.7/site-packages/flask/app.py", line 2447, in wsgi_app
    response = self.full_dispatch_request()
  File "/Users/michellewong/Documents/Speakup/venv/lib/python3.7/site-packages/flask/app.py", line 1952, in full_dispatch_request
    rv = self.handle_user_exception(e)
  File "/Users/michellewong/Documents/Speakup/venv/lib/python3.7/site-packages/flask/app.py", line 1821, in handle_user_exception
    reraise(exc_type, exc_value, tb)
  File "/Users/michellewong/Documents/Speakup/venv/lib/python3.7/site-packages/flask/_compat.py", line 39, in reraise
    raise value
  File "/Users/michellewong/Documents/Speakup/venv/lib/python3.7/site-packages/flask/app.py", line 1950, in full_dispatch_request
    rv = self.dispatch_request()
  File "/Users/michellewong/Documents/Speakup/venv/lib/python3.7/site-packages/flask/app.py", line 1936, in dispatch_request
    return self.view_functions[rule.endpoint](**req.view_args)
  File "/Users/michellewong/Documents/Speakup/app/routes.py", line 275, in reset_password_request
    send_password_reset_email(user)
NameError: name 'send_password_reset_email' is not defined
2020-09-07 16:21:22,503 INFO: Microblog startup [in /Users/michellewong/Documents/Speakup/app/__init__.py:54]
