2020-09-06 13:01:44,875 ERROR: Exception on /representative/3104 [GET] [in /Users/michellewong/Documents/Speakup/venv/lib/python3.7/site-packages/flask/app.py:1892]
Traceback (most recent call last):
  File "/Users/michellewong/Documents/Speakup/venv/lib/python3.7/site-packages/flask/app.py", line 2447, in wsgi_app
    response = self.full_dispatch_request()
  File "/Users/michellewong/Documents/Speakup/venv/lib/python3.7/site-packages/flask/app.py", line 1952, in full_dispatch_request
    rv = self.handle_user_exception(e)
  File "/Users/michellewong/Documents/Speakup/venv/lib/python3.7/site-packages/flask/app.py", line 1821, in handle_user_exception
    reraise(exc_type, exc_value, tb)
  File "/Users/michellewong/Documents/Speakup/venv/lib/python3.7/site-packages/flask/_compat.py", line 39, in reraise
    raise value
  File "/Users/michellewong/Documents/Speakup/venv/lib/python3.7/site-packages/flask/app.py", line 1950, in full_dispatch_request
    rv = self.dispatch_request()
  File "/Users/michellewong/Documents/Speakup/venv/lib/python3.7/site-packages/flask/app.py", line 1936, in dispatch_request
    return self.view_functions[rule.endpoint](**req.view_args)
  File "/Users/michellewong/Documents/Speakup/venv/lib/python3.7/site-packages/flask_login/utils.py", line 272, in decorated_view
    return func(*args, **kwargs)
  File "/Users/michellewong/Documents/Speakup/app/routes.py", line 191, in representative
    df = pandas.read_csv('Rep.csv', engine='python')
  File "/Users/michellewong/Documents/Speakup/venv/lib/python3.7/site-packages/pandas/io/parsers.py", line 686, in read_csv
    return _read(filepath_or_buffer, kwds)
  File "/Users/michellewong/Documents/Speakup/venv/lib/python3.7/site-packages/pandas/io/parsers.py", line 452, in _read
    parser = TextFileReader(fp_or_buf, **kwds)
  File "/Users/michellewong/Documents/Speakup/venv/lib/python3.7/site-packages/pandas/io/parsers.py", line 936, in __init__
    self._make_engine(self.engine)
  File "/Users/michellewong/Documents/Speakup/venv/lib/python3.7/site-packages/pandas/io/parsers.py", line 1179, in _make_engine
    self._engine = klass(self.f, **self.options)
  File "/Users/michellewong/Documents/Speakup/venv/lib/python3.7/site-packages/pandas/io/parsers.py", line 2377, in __init__
    memory_map=self.memory_map,
  File "/Users/michellewong/Documents/Speakup/venv/lib/python3.7/site-packages/pandas/io/common.py", line 496, in get_handle
    f = open(path_or_buf, mode, errors="replace", newline="")
FileNotFoundError: [Errno 2] No such file or directory: 'Rep.csv'
2020-09-06 13:02:40,787 INFO: Microblog startup [in /Users/michellewong/Documents/Speakup/app/__init__.py:50]
2020-09-06 13:02:43,676 ERROR: Exception on /representative/3104 [GET] [in /Users/michellewong/Documents/Speakup/venv/lib/python3.7/site-packages/flask/app.py:1892]
Traceback (most recent call last):
  File "/Users/michellewong/Documents/Speakup/venv/lib/python3.7/site-packages/flask/app.py", line 2447, in wsgi_app
    response = self.full_dispatch_request()
  File "/Users/michellewong/Documents/Speakup/venv/lib/python3.7/site-packages/flask/app.py", line 1952, in full_dispatch_request
    rv = self.handle_user_exception(e)
  File "/Users/michellewong/Documents/Speakup/venv/lib/python3.7/site-packages/flask/app.py", line 1821, in handle_user_exception
    reraise(exc_type, exc_value, tb)
  File "/Users/michellewong/Documents/Speakup/venv/lib/python3.7/site-packages/flask/_compat.py", line 39, in reraise
    raise value
  File "/Users/michellewong/Documents/Speakup/venv/lib/python3.7/site-packages/flask/app.py", line 1950, in full_dispatch_request
    rv = self.dispatch_request()
  File "/Users/michellewong/Documents/Speakup/venv/lib/python3.7/site-packages/flask/app.py", line 1936, in dispatch_request
    return self.view_functions[rule.endpoint](**req.view_args)
  File "/Users/michellewong/Documents/Speakup/venv/lib/python3.7/site-packages/flask_login/utils.py", line 272, in decorated_view
    return func(*args, **kwargs)
  File "/Users/michellewong/Documents/Speakup/app/routes.py", line 191, in representative
    df = pandas.read_csv('Rep.csv', engine='python')
  File "/Users/michellewong/Documents/Speakup/venv/lib/python3.7/site-packages/pandas/io/parsers.py", line 686, in read_csv
    return _read(filepath_or_buffer, kwds)
  File "/Users/michellewong/Documents/Speakup/venv/lib/python3.7/site-packages/pandas/io/parsers.py", line 452, in _read
    parser = TextFileReader(fp_or_buf, **kwds)
  File "/Users/michellewong/Documents/Speakup/venv/lib/python3.7/site-packages/pandas/io/parsers.py", line 936, in __init__
    self._make_engine(self.engine)
  File "/Users/michellewong/Documents/Speakup/venv/lib/python3.7/site-packages/pandas/io/parsers.py", line 1179, in _make_engine
    self._engine = klass(self.f, **self.options)
  File "/Users/michellewong/Documents/Speakup/venv/lib/python3.7/site-packages/pandas/io/parsers.py", line 2377, in __init__
    memory_map=self.memory_map,
  File "/Users/michellewong/Documents/Speakup/venv/lib/python3.7/site-packages/pandas/io/common.py", line 496, in get_handle
    f = open(path_or_buf, mode, errors="replace", newline="")
FileNotFoundError: [Errno 2] No such file or directory: 'Rep.csv'
2020-09-06 13:04:41,664 INFO: Microblog startup [in /Users/michellewong/Documents/Speakup/app/__init__.py:50]
2020-09-06 13:04:47,244 ERROR: Exception on /representative/3104 [GET] [in /Users/michellewong/Documents/Speakup/venv/lib/python3.7/site-packages/flask/app.py:1892]
Traceback (most recent call last):
  File "/Users/michellewong/Documents/Speakup/venv/lib/python3.7/site-packages/flask/app.py", line 2447, in wsgi_app
    response = self.full_dispatch_request()
  File "/Users/michellewong/Documents/Speakup/venv/lib/python3.7/site-packages/flask/app.py", line 1952, in full_dispatch_request
    rv = self.handle_user_exception(e)
  File "/Users/michellewong/Documents/Speakup/venv/lib/python3.7/site-packages/flask/app.py", line 1821, in handle_user_exception
    reraise(exc_type, exc_value, tb)
  File "/Users/michellewong/Documents/Speakup/venv/lib/python3.7/site-packages/flask/_compat.py", line 39, in reraise
    raise value
  File "/Users/michellewong/Documents/Speakup/venv/lib/python3.7/site-packages/flask/app.py", line 1950, in full_dispatch_request
    rv = self.dispatch_request()
  File "/Users/michellewong/Documents/Speakup/venv/lib/python3.7/site-packages/flask/app.py", line 1936, in dispatch_request
    return self.view_functions[rule.endpoint](**req.view_args)
  File "/Users/michellewong/Documents/Speakup/venv/lib/python3.7/site-packages/flask_login/utils.py", line 272, in decorated_view
    return func(*args, **kwargs)
  File "/Users/michellewong/Documents/Speakup/app/routes.py", line 191, in representative
    df = pandas.read_csv('static/Rep.csv', engine='python')
  File "/Users/michellewong/Documents/Speakup/venv/lib/python3.7/site-packages/pandas/io/parsers.py", line 686, in read_csv
    return _read(filepath_or_buffer, kwds)
  File "/Users/michellewong/Documents/Speakup/venv/lib/python3.7/site-packages/pandas/io/parsers.py", line 452, in _read
    parser = TextFileReader(fp_or_buf, **kwds)
  File "/Users/michellewong/Documents/Speakup/venv/lib/python3.7/site-packages/pandas/io/parsers.py", line 936, in __init__
    self._make_engine(self.engine)
  File "/Users/michellewong/Documents/Speakup/venv/lib/python3.7/site-packages/pandas/io/parsers.py", line 1179, in _make_engine
    self._engine = klass(self.f, **self.options)
  File "/Users/michellewong/Documents/Speakup/venv/lib/python3.7/site-packages/pandas/io/parsers.py", line 2377, in __init__
    memory_map=self.memory_map,
  File "/Users/michellewong/Documents/Speakup/venv/lib/python3.7/site-packages/pandas/io/common.py", line 496, in get_handle
    f = open(path_or_buf, mode, errors="replace", newline="")
FileNotFoundError: [Errno 2] No such file or directory: 'static/Rep.csv'
2020-09-06 13:07:41,468 INFO: Microblog startup [in /Users/michellewong/Documents/Speakup/app/__init__.py:50]
