2020-09-11 19:10:50,616 ERROR: Exception on /index [GET] [in /Users/michellewong/Documents/Speakup/venv/lib/python3.7/site-packages/flask/app.py:1892]
Traceback (most recent call last):
  File "/Users/michellewong/Documents/Speakup/venv/lib/python3.7/site-packages/sqlalchemy/engine/base.py", line 1277, in _execute_context
    cursor, statement, parameters, context
  File "/Users/michellewong/Documents/Speakup/venv/lib/python3.7/site-packages/sqlalchemy/engine/default.py", line 593, in do_execute
    cursor.execute(statement, parameters)
sqlite3.OperationalError: no such table: senate

The above exception was the direct cause of the following exception:

Traceback (most recent call last):
  File "/Users/michellewong/Documents/Speakup/venv/lib/python3.7/site-packages/flask/app.py", line 2447, in wsgi_app
    response = self.full_dispatch_request()
  File "/Users/michellewong/Documents/Speakup/venv/lib/python3.7/site-packages/flask/app.py", line 1952, in full_dispatch_request
    rv = self.handle_user_exception(e)
  File "/Users/michellewong/Documents/Speakup/venv/lib/python3.7/site-packages/flask/app.py", line 1821, in handle_user_exception
    reraise(exc_type, exc_value, tb)
  File "/Users/michellewong/Documents/Speakup/venv/lib/python3.7/site-packages/flask/_compat.py", line 39, in reraise
    raise value
  File "/Users/michellewong/Documents/Speakup/venv/lib/python3.7/site-packages/flask/app.py", line 1948, in full_dispatch_request
    rv = self.preprocess_request()
  File "/Users/michellewong/Documents/Speakup/venv/lib/python3.7/site-packages/flask/app.py", line 2242, in preprocess_request
    rv = func()
  File "/Users/michellewong/Documents/Speakup/app/main/routes.py", line 27, in before_request
    buildrep()
  File "/Users/michellewong/Documents/Speakup/app/senatedatabase.py", line 37, in buildrep
    db.session.commit()
  File "/Users/michellewong/Documents/Speakup/venv/lib/python3.7/site-packages/sqlalchemy/orm/scoping.py", line 163, in do
    return getattr(self.registry(), name)(*args, **kwargs)
  File "/Users/michellewong/Documents/Speakup/venv/lib/python3.7/site-packages/sqlalchemy/orm/session.py", line 1042, in commit
    self.transaction.commit()
  File "/Users/michellewong/Documents/Speakup/venv/lib/python3.7/site-packages/sqlalchemy/orm/session.py", line 504, in commit
    self._prepare_impl()
  File "/Users/michellewong/Documents/Speakup/venv/lib/python3.7/site-packages/sqlalchemy/orm/session.py", line 483, in _prepare_impl
    self.session.flush()
  File "/Users/michellewong/Documents/Speakup/venv/lib/python3.7/site-packages/sqlalchemy/orm/session.py", line 2523, in flush
    self._flush(objects)
  File "/Users/michellewong/Documents/Speakup/venv/lib/python3.7/site-packages/sqlalchemy/orm/session.py", line 2664, in _flush
    transaction.rollback(_capture_exception=True)
  File "/Users/michellewong/Documents/Speakup/venv/lib/python3.7/site-packages/sqlalchemy/util/langhelpers.py", line 69, in __exit__
    exc_value, with_traceback=exc_tb,
  File "/Users/michellewong/Documents/Speakup/venv/lib/python3.7/site-packages/sqlalchemy/util/compat.py", line 182, in raise_
    raise exception
  File "/Users/michellewong/Documents/Speakup/venv/lib/python3.7/site-packages/sqlalchemy/orm/session.py", line 2624, in _flush
    flush_context.execute()
  File "/Users/michellewong/Documents/Speakup/venv/lib/python3.7/site-packages/sqlalchemy/orm/unitofwork.py", line 422, in execute
    rec.execute(self)
  File "/Users/michellewong/Documents/Speakup/venv/lib/python3.7/site-packages/sqlalchemy/orm/unitofwork.py", line 589, in execute
    uow,
  File "/Users/michellewong/Documents/Speakup/venv/lib/python3.7/site-packages/sqlalchemy/orm/persistence.py", line 245, in save_obj
    insert,
  File "/Users/michellewong/Documents/Speakup/venv/lib/python3.7/site-packages/sqlalchemy/orm/persistence.py", line 1136, in _emit_insert_statements
    statement, params
  File "/Users/michellewong/Documents/Speakup/venv/lib/python3.7/site-packages/sqlalchemy/engine/base.py", line 1011, in execute
    return meth(self, multiparams, params)
  File "/Users/michellewong/Documents/Speakup/venv/lib/python3.7/site-packages/sqlalchemy/sql/elements.py", line 298, in _execute_on_connection
    return connection._execute_clauseelement(self, multiparams, params)
  File "/Users/michellewong/Documents/Speakup/venv/lib/python3.7/site-packages/sqlalchemy/engine/base.py", line 1130, in _execute_clauseelement
    distilled_params,
  File "/Users/michellewong/Documents/Speakup/venv/lib/python3.7/site-packages/sqlalchemy/engine/base.py", line 1317, in _execute_context
    e, statement, parameters, cursor, context
  File "/Users/michellewong/Documents/Speakup/venv/lib/python3.7/site-packages/sqlalchemy/engine/base.py", line 1511, in _handle_dbapi_exception
    sqlalchemy_exception, with_traceback=exc_info[2], from_=e
  File "/Users/michellewong/Documents/Speakup/venv/lib/python3.7/site-packages/sqlalchemy/util/compat.py", line 182, in raise_
    raise exception
  File "/Users/michellewong/Documents/Speakup/venv/lib/python3.7/site-packages/sqlalchemy/engine/base.py", line 1277, in _execute_context
    cursor, statement, parameters, context
  File "/Users/michellewong/Documents/Speakup/venv/lib/python3.7/site-packages/sqlalchemy/engine/default.py", line 593, in do_execute
    cursor.execute(statement, parameters)
sqlalchemy.exc.OperationalError: (sqlite3.OperationalError) no such table: senate
[SQL: INSERT INTO senate (title, "Image", "Surname", "FirstName", "PreferredName", "Email", "Facebook", "Twitter", "Other", "ElectorateAddress", "ElectoratePhone", "ElectoratePostal", "ElectorateSuburb", "Titles", "Postcode") VALUES (?, ?, ?, ?, ?, ?, ?, ?, ?, ?, ?, ?, ?, ?, ?)]
[parameters: ('Senator the Hon', '10003.jpg', 'Abetz', 'Eric', 'Eric', nan, 'http://www.facebook.com/SenatorAbetz', nan, nan, 'Highbury House, 136 Davey Street, Hobart, TAS, 7000', '(03) 6224 3707', 'GPO Box 1675, Hobart, TAS, 7001', 'Hobart', nan, 7000)]
(Background on this error at: http://sqlalche.me/e/13/e3q8)
2020-09-11 19:11:06,023 INFO: Microblog startup [in /Users/michellewong/Documents/Speakup/app/__init__.py:87]
2020-09-11 19:11:51,393 INFO: Microblog startup [in /Users/michellewong/Documents/Speakup/app/__init__.py:87]
2020-09-11 19:13:42,536 INFO: Microblog startup [in /Users/michellewong/Documents/Speakup/app/__init__.py:87]
2020-09-11 19:14:36,778 INFO: Microblog startup [in /Users/michellewong/Documents/Speakup/app/__init__.py:90]
2020-09-11 19:16:03,501 INFO: Microblog startup [in /Users/michellewong/Documents/Speakup/app/__init__.py:90]
2020-09-11 19:17:23,464 INFO: Microblog startup [in /Users/michellewong/Documents/Speakup/app/__init__.py:90]
2020-09-11 19:18:02,105 INFO: Microblog startup [in /Users/michellewong/Documents/Speakup/app/__init__.py:90]
2020-09-11 19:18:04,880 ERROR: Exception on /senators [GET] [in /Users/michellewong/Documents/Speakup/venv/lib/python3.7/site-packages/flask/app.py:1892]
Traceback (most recent call last):
  File "/Users/michellewong/Documents/Speakup/venv/lib/python3.7/site-packages/flask/app.py", line 2447, in wsgi_app
    response = self.full_dispatch_request()
  File "/Users/michellewong/Documents/Speakup/venv/lib/python3.7/site-packages/flask/app.py", line 1952, in full_dispatch_request
    rv = self.handle_user_exception(e)
  File "/Users/michellewong/Documents/Speakup/venv/lib/python3.7/site-packages/flask/app.py", line 1821, in handle_user_exception
    reraise(exc_type, exc_value, tb)
  File "/Users/michellewong/Documents/Speakup/venv/lib/python3.7/site-packages/flask/_compat.py", line 39, in reraise
    raise value
  File "/Users/michellewong/Documents/Speakup/venv/lib/python3.7/site-packages/flask/app.py", line 1950, in full_dispatch_request
    rv = self.dispatch_request()
  File "/Users/michellewong/Documents/Speakup/venv/lib/python3.7/site-packages/flask/app.py", line 1936, in dispatch_request
    return self.view_functions[rule.endpoint](**req.view_args)
  File "/Users/michellewong/Documents/Speakup/venv/lib/python3.7/site-packages/flask_login/utils.py", line 272, in decorated_view
    return func(*args, **kwargs)
  File "/Users/michellewong/Documents/Speakup/app/rep/routes.py", line 72, in allsenators
    reps = Senate.query.paginate(
NameError: name 'Senate' is not defined
2020-09-11 19:18:53,948 INFO: Microblog startup [in /Users/michellewong/Documents/Speakup/app/__init__.py:90]
2020-09-11 19:21:44,585 INFO: Microblog startup [in /Users/michellewong/Documents/Speakup/app/__init__.py:90]
2020-09-11 19:23:45,824 INFO: Microblog startup [in /Users/michellewong/Documents/Speakup/app/__init__.py:90]
2020-09-11 19:34:46,428 INFO: Microblog startup [in /Users/michellewong/Documents/Speakup/app/__init__.py:90]
