2020-09-10 14:01:49,230 ERROR: Exception on /notifications [GET] [in /Users/michellewong/Documents/Speakup/venv/lib/python3.7/site-packages/flask/app.py:1892]
Traceback (most recent call last):
  File "/Users/michellewong/Documents/Speakup/venv/lib/python3.7/site-packages/flask/app.py", line 2447, in wsgi_app
    response = self.full_dispatch_request()
  File "/Users/michellewong/Documents/Speakup/venv/lib/python3.7/site-packages/flask/app.py", line 1952, in full_dispatch_request
    rv = self.handle_user_exception(e)
  File "/Users/michellewong/Documents/Speakup/venv/lib/python3.7/site-packages/flask/app.py", line 1821, in handle_user_exception
    reraise(exc_type, exc_value, tb)
  File "/Users/michellewong/Documents/Speakup/venv/lib/python3.7/site-packages/flask/_compat.py", line 39, in reraise
    raise value
  File "/Users/michellewong/Documents/Speakup/venv/lib/python3.7/site-packages/flask/app.py", line 1948, in full_dispatch_request
    rv = self.preprocess_request()
  File "/Users/michellewong/Documents/Speakup/venv/lib/python3.7/site-packages/flask/app.py", line 2242, in preprocess_request
    rv = func()
  File "/Users/michellewong/Documents/Speakup/app/main/routes.py", line 23, in before_request
    if Task.query.filter_by(description=datetime.datetime.now().date().strftime('%m/%d/%Y')):
NameError: name 'Task' is not defined
2020-09-10 14:01:52,695 ERROR: Exception on /index [GET] [in /Users/michellewong/Documents/Speakup/venv/lib/python3.7/site-packages/flask/app.py:1892]
Traceback (most recent call last):
  File "/Users/michellewong/Documents/Speakup/venv/lib/python3.7/site-packages/flask/app.py", line 2447, in wsgi_app
    response = self.full_dispatch_request()
  File "/Users/michellewong/Documents/Speakup/venv/lib/python3.7/site-packages/flask/app.py", line 1952, in full_dispatch_request
    rv = self.handle_user_exception(e)
  File "/Users/michellewong/Documents/Speakup/venv/lib/python3.7/site-packages/flask/app.py", line 1821, in handle_user_exception
    reraise(exc_type, exc_value, tb)
  File "/Users/michellewong/Documents/Speakup/venv/lib/python3.7/site-packages/flask/_compat.py", line 39, in reraise
    raise value
  File "/Users/michellewong/Documents/Speakup/venv/lib/python3.7/site-packages/flask/app.py", line 1948, in full_dispatch_request
    rv = self.preprocess_request()
  File "/Users/michellewong/Documents/Speakup/venv/lib/python3.7/site-packages/flask/app.py", line 2242, in preprocess_request
    rv = func()
  File "/Users/michellewong/Documents/Speakup/app/main/routes.py", line 23, in before_request
    if Task.query.filter_by(description=datetime.datetime.now().date().strftime('%m/%d/%Y')):
NameError: name 'Task' is not defined
2020-09-10 14:02:07,670 INFO: Microblog startup [in /Users/michellewong/Documents/Speakup/app/__init__.py:88]
2020-09-10 14:02:10,386 ERROR: Exception on /index [GET] [in /Users/michellewong/Documents/Speakup/venv/lib/python3.7/site-packages/flask/app.py:1892]
Traceback (most recent call last):
  File "/Users/michellewong/Documents/Speakup/venv/lib/python3.7/site-packages/flask/app.py", line 2447, in wsgi_app
    response = self.full_dispatch_request()
  File "/Users/michellewong/Documents/Speakup/venv/lib/python3.7/site-packages/flask/app.py", line 1952, in full_dispatch_request
    rv = self.handle_user_exception(e)
  File "/Users/michellewong/Documents/Speakup/venv/lib/python3.7/site-packages/flask/app.py", line 1821, in handle_user_exception
    reraise(exc_type, exc_value, tb)
  File "/Users/michellewong/Documents/Speakup/venv/lib/python3.7/site-packages/flask/_compat.py", line 39, in reraise
    raise value
  File "/Users/michellewong/Documents/Speakup/venv/lib/python3.7/site-packages/flask/app.py", line 1948, in full_dispatch_request
    rv = self.preprocess_request()
  File "/Users/michellewong/Documents/Speakup/venv/lib/python3.7/site-packages/flask/app.py", line 2242, in preprocess_request
    rv = func()
  File "/Users/michellewong/Documents/Speakup/app/main/routes.py", line 23, in before_request
    if Task.query.filter_by(description=datetime.datetime.now().date().strftime('%m/%d/%Y')):
AttributeError: type object 'datetime.datetime' has no attribute 'datetime'
2020-09-10 14:02:30,799 INFO: Microblog startup [in /Users/michellewong/Documents/Speakup/app/__init__.py:88]
2020-09-10 14:02:35,324 ERROR: Exception on /index [GET] [in /Users/michellewong/Documents/Speakup/venv/lib/python3.7/site-packages/flask/app.py:1892]
Traceback (most recent call last):
  File "/Users/michellewong/Documents/Speakup/venv/lib/python3.7/site-packages/flask/app.py", line 2447, in wsgi_app
    response = self.full_dispatch_request()
  File "/Users/michellewong/Documents/Speakup/venv/lib/python3.7/site-packages/flask/app.py", line 1952, in full_dispatch_request
    rv = self.handle_user_exception(e)
  File "/Users/michellewong/Documents/Speakup/venv/lib/python3.7/site-packages/flask/app.py", line 1821, in handle_user_exception
    reraise(exc_type, exc_value, tb)
  File "/Users/michellewong/Documents/Speakup/venv/lib/python3.7/site-packages/flask/_compat.py", line 39, in reraise
    raise value
  File "/Users/michellewong/Documents/Speakup/venv/lib/python3.7/site-packages/flask/app.py", line 1948, in full_dispatch_request
    rv = self.preprocess_request()
  File "/Users/michellewong/Documents/Speakup/venv/lib/python3.7/site-packages/flask/app.py", line 2242, in preprocess_request
    rv = func()
  File "/Users/michellewong/Documents/Speakup/app/main/routes.py", line 21, in before_request
    current_user.last_seen = datetime.utcnow()
AttributeError: module 'datetime' has no attribute 'utcnow'
2020-09-10 14:03:15,898 INFO: Microblog startup [in /Users/michellewong/Documents/Speakup/app/__init__.py:88]
2020-09-10 14:03:21,357 ERROR: Exception on /index [GET] [in /Users/michellewong/Documents/Speakup/venv/lib/python3.7/site-packages/flask/app.py:1892]
Traceback (most recent call last):
  File "/Users/michellewong/Documents/Speakup/venv/lib/python3.7/site-packages/flask/app.py", line 2447, in wsgi_app
    response = self.full_dispatch_request()
  File "/Users/michellewong/Documents/Speakup/venv/lib/python3.7/site-packages/flask/app.py", line 1952, in full_dispatch_request
    rv = self.handle_user_exception(e)
  File "/Users/michellewong/Documents/Speakup/venv/lib/python3.7/site-packages/flask/app.py", line 1821, in handle_user_exception
    reraise(exc_type, exc_value, tb)
  File "/Users/michellewong/Documents/Speakup/venv/lib/python3.7/site-packages/flask/_compat.py", line 39, in reraise
    raise value
  File "/Users/michellewong/Documents/Speakup/venv/lib/python3.7/site-packages/flask/app.py", line 1948, in full_dispatch_request
    rv = self.preprocess_request()
  File "/Users/michellewong/Documents/Speakup/venv/lib/python3.7/site-packages/flask/app.py", line 2242, in preprocess_request
    rv = func()
  File "/Users/michellewong/Documents/Speakup/app/main/routes.py", line 25, in before_request
    current_user.launch_task('build_hansard', 'Exporting posts...',datetime.datetime.now().date().strftime('%m/%d/%Y'))
AttributeError: type object 'datetime.datetime' has no attribute 'datetime'
2020-09-10 14:03:40,441 INFO: Microblog startup [in /Users/michellewong/Documents/Speakup/app/__init__.py:88]
2020-09-10 14:03:43,068 INFO: Microblog startup [in ./app/__init__.py:88]
2020-09-10 14:03:53,223 INFO: Microblog startup [in ./app/__init__.py:88]
2020-09-10 14:04:03,194 INFO: Microblog startup [in ./app/__init__.py:88]
2020-09-10 14:04:13,653 INFO: Microblog startup [in /Users/michellewong/Documents/Speakup/app/__init__.py:88]
2020-09-10 14:04:23,265 INFO: Microblog startup [in ./app/__init__.py:88]
2020-09-10 14:04:33,244 INFO: Microblog startup [in ./app/__init__.py:88]
2020-09-10 14:04:43,170 INFO: Microblog startup [in ./app/__init__.py:88]
2020-09-10 14:04:53,202 INFO: Microblog startup [in ./app/__init__.py:88]
2020-09-10 14:05:03,290 INFO: Microblog startup [in ./app/__init__.py:88]
2020-09-10 14:05:10,822 INFO: Microblog startup [in /Users/michellewong/Documents/Speakup/app/__init__.py:88]
2020-09-10 14:05:13,229 INFO: Microblog startup [in ./app/__init__.py:88]
2020-09-10 14:05:23,256 INFO: Microblog startup [in ./app/__init__.py:88]
2020-09-10 14:05:33,197 INFO: Microblog startup [in ./app/__init__.py:88]
2020-09-10 14:05:43,218 INFO: Microblog startup [in ./app/__init__.py:88]
2020-09-10 14:05:53,282 INFO: Microblog startup [in ./app/__init__.py:88]
2020-09-10 14:06:03,215 INFO: Microblog startup [in ./app/__init__.py:88]
2020-09-10 14:06:13,211 INFO: Microblog startup [in ./app/__init__.py:88]
2020-09-10 14:07:32,089 INFO: Microblog startup [in /Users/michellewong/Documents/Speakup/app/__init__.py:88]
2020-09-10 14:07:40,459 INFO: Microblog startup [in ./app/__init__.py:88]
2020-09-10 14:07:50,630 INFO: Microblog startup [in ./app/__init__.py:88]
2020-09-10 14:08:00,677 INFO: Microblog startup [in ./app/__init__.py:88]
2020-09-10 14:08:10,698 INFO: Microblog startup [in ./app/__init__.py:88]
2020-09-10 14:08:20,680 INFO: Microblog startup [in ./app/__init__.py:88]
2020-09-10 14:08:30,651 INFO: Microblog startup [in ./app/__init__.py:88]
2020-09-10 14:08:40,746 INFO: Microblog startup [in ./app/__init__.py:88]
2020-09-10 14:08:50,642 INFO: Microblog startup [in ./app/__init__.py:88]
2020-09-10 14:09:00,010 INFO: Microblog startup [in /Users/michellewong/Documents/Speakup/app/__init__.py:88]
2020-09-10 14:09:01,617 INFO: Microblog startup [in ./app/__init__.py:88]
2020-09-10 14:09:01,925 ERROR: Unhandled exception [in ./app/tasks.py:70]
Traceback (most recent call last):
  File "./app/tasks.py", line 62, in rebuild_hansard
    if Hansard.query.filter_by(date=date).first():
NameError: name 'Hansard' is not defined
2020-09-10 14:09:11,855 INFO: Microblog startup [in ./app/__init__.py:88]
2020-09-10 14:09:12,121 ERROR: Unhandled exception [in ./app/tasks.py:70]
Traceback (most recent call last):
  File "./app/tasks.py", line 62, in rebuild_hansard
    if Hansard.query.filter_by(date=date).first():
NameError: name 'Hansard' is not defined
2020-09-10 14:09:21,872 INFO: Microblog startup [in ./app/__init__.py:88]
