2020-09-06 12:33:16,568 ERROR: Exception on /representative/10741 [GET] [in /Users/michellewong/Documents/Speakup/venv/lib/python3.7/site-packages/flask/app.py:1892]
Traceback (most recent call last):
  File "/Users/michellewong/Documents/Speakup/venv/lib/python3.7/site-packages/flask/app.py", line 2447, in wsgi_app
    response = self.full_dispatch_request()
  File "/Users/michellewong/Documents/Speakup/venv/lib/python3.7/site-packages/flask/app.py", line 1952, in full_dispatch_request
    rv = self.handle_user_exception(e)
  File "/Users/michellewong/Documents/Speakup/venv/lib/python3.7/site-packages/flask/app.py", line 1821, in handle_user_exception
    reraise(exc_type, exc_value, tb)
  File "/Users/michellewong/Documents/Speakup/venv/lib/python3.7/site-packages/flask/_compat.py", line 39, in reraise
    raise value
  File "/Users/michellewong/Documents/Speakup/venv/lib/python3.7/site-packages/flask/app.py", line 1950, in full_dispatch_request
    rv = self.dispatch_request()
  File "/Users/michellewong/Documents/Speakup/venv/lib/python3.7/site-packages/flask/app.py", line 1936, in dispatch_request
    return self.view_functions[rule.endpoint](**req.view_args)
  File "/Users/michellewong/Documents/Speakup/venv/lib/python3.7/site-packages/flask_login/utils.py", line 272, in decorated_view
    return func(*args, **kwargs)
  File "/Users/michellewong/Documents/Speakup/app/routes.py", line 182, in representative
    response = requests.get('https://theyvoteforyou.org.au/api/v1/people/'+person_id+'.json?key=k4Pwf%2BFaW2ygOTWEOCVn')
NameError: name 'person_id' is not defined
2020-09-06 12:33:34,474 INFO: Microblog startup [in /Users/michellewong/Documents/Speakup/app/__init__.py:50]
2020-09-06 12:33:36,344 ERROR: Exception on /representative/10741 [GET] [in /Users/michellewong/Documents/Speakup/venv/lib/python3.7/site-packages/flask/app.py:1892]
Traceback (most recent call last):
  File "/Users/michellewong/Documents/Speakup/venv/lib/python3.7/site-packages/flask/app.py", line 2447, in wsgi_app
    response = self.full_dispatch_request()
  File "/Users/michellewong/Documents/Speakup/venv/lib/python3.7/site-packages/flask/app.py", line 1952, in full_dispatch_request
    rv = self.handle_user_exception(e)
  File "/Users/michellewong/Documents/Speakup/venv/lib/python3.7/site-packages/flask/app.py", line 1821, in handle_user_exception
    reraise(exc_type, exc_value, tb)
  File "/Users/michellewong/Documents/Speakup/venv/lib/python3.7/site-packages/flask/_compat.py", line 39, in reraise
    raise value
  File "/Users/michellewong/Documents/Speakup/venv/lib/python3.7/site-packages/flask/app.py", line 1950, in full_dispatch_request
    rv = self.dispatch_request()
  File "/Users/michellewong/Documents/Speakup/venv/lib/python3.7/site-packages/flask/app.py", line 1936, in dispatch_request
    return self.view_functions[rule.endpoint](**req.view_args)
  File "/Users/michellewong/Documents/Speakup/venv/lib/python3.7/site-packages/flask_login/utils.py", line 272, in decorated_view
    return func(*args, **kwargs)
  File "/Users/michellewong/Documents/Speakup/app/routes.py", line 185, in representative
    return render_template('rep.html', data = json_data, image = image, oa = oa_data, excel = value)
NameError: name 'oa_data' is not defined
2020-09-06 12:41:11,410 INFO: Microblog startup [in /Users/michellewong/Documents/Speakup/app/__init__.py:50]
2020-09-06 12:41:33,819 INFO: Microblog startup [in /Users/michellewong/Documents/Speakup/app/__init__.py:50]
2020-09-06 12:41:40,301 ERROR: Exception on /representative/3104 [GET] [in /Users/michellewong/Documents/Speakup/venv/lib/python3.7/site-packages/flask/app.py:1892]
Traceback (most recent call last):
  File "/Users/michellewong/Documents/Speakup/venv/lib/python3.7/site-packages/flask/app.py", line 2447, in wsgi_app
    response = self.full_dispatch_request()
  File "/Users/michellewong/Documents/Speakup/venv/lib/python3.7/site-packages/flask/app.py", line 1952, in full_dispatch_request
    rv = self.handle_user_exception(e)
  File "/Users/michellewong/Documents/Speakup/venv/lib/python3.7/site-packages/flask/app.py", line 1821, in handle_user_exception
    reraise(exc_type, exc_value, tb)
  File "/Users/michellewong/Documents/Speakup/venv/lib/python3.7/site-packages/flask/_compat.py", line 39, in reraise
    raise value
  File "/Users/michellewong/Documents/Speakup/venv/lib/python3.7/site-packages/flask/app.py", line 1950, in full_dispatch_request
    rv = self.dispatch_request()
  File "/Users/michellewong/Documents/Speakup/venv/lib/python3.7/site-packages/flask/app.py", line 1936, in dispatch_request
    return self.view_functions[rule.endpoint](**req.view_args)
  File "/Users/michellewong/Documents/Speakup/venv/lib/python3.7/site-packages/flask_login/utils.py", line 272, in decorated_view
    return func(*args, **kwargs)
  File "/Users/michellewong/Documents/Speakup/app/routes.py", line 183, in representative
    person_id = oa_date['person_id']
NameError: name 'oa_date' is not defined
2020-09-06 12:41:51,414 INFO: Microblog startup [in /Users/michellewong/Documents/Speakup/app/__init__.py:50]
2020-09-06 12:41:53,253 ERROR: Exception on /representative/3104 [GET] [in /Users/michellewong/Documents/Speakup/venv/lib/python3.7/site-packages/flask/app.py:1892]
Traceback (most recent call last):
  File "/Users/michellewong/Documents/Speakup/venv/lib/python3.7/site-packages/flask/app.py", line 2447, in wsgi_app
    response = self.full_dispatch_request()
  File "/Users/michellewong/Documents/Speakup/venv/lib/python3.7/site-packages/flask/app.py", line 1952, in full_dispatch_request
    rv = self.handle_user_exception(e)
  File "/Users/michellewong/Documents/Speakup/venv/lib/python3.7/site-packages/flask/app.py", line 1821, in handle_user_exception
    reraise(exc_type, exc_value, tb)
  File "/Users/michellewong/Documents/Speakup/venv/lib/python3.7/site-packages/flask/_compat.py", line 39, in reraise
    raise value
  File "/Users/michellewong/Documents/Speakup/venv/lib/python3.7/site-packages/flask/app.py", line 1950, in full_dispatch_request
    rv = self.dispatch_request()
  File "/Users/michellewong/Documents/Speakup/venv/lib/python3.7/site-packages/flask/app.py", line 1936, in dispatch_request
    return self.view_functions[rule.endpoint](**req.view_args)
  File "/Users/michellewong/Documents/Speakup/venv/lib/python3.7/site-packages/flask_login/utils.py", line 272, in decorated_view
    return func(*args, **kwargs)
  File "/Users/michellewong/Documents/Speakup/app/routes.py", line 184, in representative
    response = requests.get('https://theyvoteforyou.org.au/api/v1/people/'+id+'.json?key=k4Pwf%2BFaW2ygOTWEOCVn')
TypeError: can only concatenate str (not "builtin_function_or_method") to str
2020-09-06 12:42:21,951 INFO: Microblog startup [in /Users/michellewong/Documents/Speakup/app/__init__.py:50]
2020-09-06 12:42:24,459 ERROR: Exception on /representative/3104 [GET] [in /Users/michellewong/Documents/Speakup/venv/lib/python3.7/site-packages/flask/app.py:1892]
Traceback (most recent call last):
  File "/Users/michellewong/Documents/Speakup/venv/lib/python3.7/site-packages/flask/app.py", line 2447, in wsgi_app
    response = self.full_dispatch_request()
  File "/Users/michellewong/Documents/Speakup/venv/lib/python3.7/site-packages/flask/app.py", line 1952, in full_dispatch_request
    rv = self.handle_user_exception(e)
  File "/Users/michellewong/Documents/Speakup/venv/lib/python3.7/site-packages/flask/app.py", line 1821, in handle_user_exception
    reraise(exc_type, exc_value, tb)
  File "/Users/michellewong/Documents/Speakup/venv/lib/python3.7/site-packages/flask/_compat.py", line 39, in reraise
    raise value
  File "/Users/michellewong/Documents/Speakup/venv/lib/python3.7/site-packages/flask/app.py", line 1950, in full_dispatch_request
    rv = self.dispatch_request()
  File "/Users/michellewong/Documents/Speakup/venv/lib/python3.7/site-packages/flask/app.py", line 1936, in dispatch_request
    return self.view_functions[rule.endpoint](**req.view_args)
  File "/Users/michellewong/Documents/Speakup/venv/lib/python3.7/site-packages/flask_login/utils.py", line 272, in decorated_view
    return func(*args, **kwargs)
  File "/Users/michellewong/Documents/Speakup/app/routes.py", line 185, in representative
    json_data = json.loads(response.text)
  File "/Users/michellewong/opt/anaconda3/lib/python3.7/json/__init__.py", line 348, in loads
    return _default_decoder.decode(s)
  File "/Users/michellewong/opt/anaconda3/lib/python3.7/json/decoder.py", line 340, in decode
    raise JSONDecodeError("Extra data", s, end)
json.decoder.JSONDecodeError: Extra data: line 1 column 5 (char 4)
2020-09-06 12:42:53,032 INFO: Microblog startup [in /Users/michellewong/Documents/Speakup/app/__init__.py:50]
2020-09-06 12:43:37,781 INFO: Microblog startup [in /Users/michellewong/Documents/Speakup/app/__init__.py:50]
2020-09-06 12:46:49,688 INFO: Microblog startup [in /Users/michellewong/Documents/Speakup/app/__init__.py:50]
2020-09-06 12:50:25,171 INFO: Microblog startup [in /Users/michellewong/Documents/Speakup/app/__init__.py:50]
2020-09-06 12:51:18,012 INFO: Microblog startup [in /Users/michellewong/Documents/Speakup/app/__init__.py:50]
2020-09-06 12:51:37,211 INFO: Microblog startup [in /Users/michellewong/Documents/Speakup/app/__init__.py:50]
2020-09-06 12:51:50,302 INFO: Microblog startup [in /Users/michellewong/Documents/Speakup/app/__init__.py:50]
2020-09-06 13:00:53,003 INFO: Microblog startup [in /Users/michellewong/Documents/Speakup/app/__init__.py:50]
