2020-08-31 11:45:55,776 ERROR: Exception on /myrepresentative [GET] [in /Users/michellewong/Documents/Speakup/venv/lib/python3.7/site-packages/flask/app.py:1892]
Traceback (most recent call last):
  File "/Users/michellewong/Documents/Speakup/venv/lib/python3.7/site-packages/flask/app.py", line 2447, in wsgi_app
    response = self.full_dispatch_request()
  File "/Users/michellewong/Documents/Speakup/venv/lib/python3.7/site-packages/flask/app.py", line 1952, in full_dispatch_request
    rv = self.handle_user_exception(e)
  File "/Users/michellewong/Documents/Speakup/venv/lib/python3.7/site-packages/flask/app.py", line 1821, in handle_user_exception
    reraise(exc_type, exc_value, tb)
  File "/Users/michellewong/Documents/Speakup/venv/lib/python3.7/site-packages/flask/_compat.py", line 39, in reraise
    raise value
  File "/Users/michellewong/Documents/Speakup/venv/lib/python3.7/site-packages/flask/app.py", line 1950, in full_dispatch_request
    rv = self.dispatch_request()
  File "/Users/michellewong/Documents/Speakup/venv/lib/python3.7/site-packages/flask/app.py", line 1936, in dispatch_request
    return self.view_functions[rule.endpoint](**req.view_args)
  File "/Users/michellewong/Documents/Speakup/venv/lib/python3.7/site-packages/flask_login/utils.py", line 272, in decorated_view
    return func(*args, **kwargs)
  File "/Users/michellewong/Documents/Speakup/app/routes.py", line 169, in myrepresentative
    image = "https://www.openaustralia.org.au/images/mpsL/"+json_data['id']+".jpg"
TypeError: can only concatenate str (not "int") to str
2020-08-31 11:46:24,482 INFO: Microblog startup [in /Users/michellewong/Documents/Speakup/app/__init__.py:46]
2020-08-31 11:50:17,193 INFO: Microblog startup [in /Users/michellewong/Documents/Speakup/app/__init__.py:46]
2020-08-31 11:52:03,262 INFO: Microblog startup [in /Users/michellewong/Documents/Speakup/app/__init__.py:46]
2020-08-31 11:54:42,771 INFO: Microblog startup [in /Users/michellewong/Documents/Speakup/app/__init__.py:46]
2020-08-31 11:55:17,309 INFO: Microblog startup [in /Users/michellewong/Documents/Speakup/app/__init__.py:46]
2020-08-31 11:55:45,835 INFO: Microblog startup [in /Users/michellewong/Documents/Speakup/app/__init__.py:46]
2020-08-31 11:56:03,895 INFO: Microblog startup [in /Users/michellewong/Documents/Speakup/app/__init__.py:46]
2020-08-31 11:56:33,713 INFO: Microblog startup [in /Users/michellewong/Documents/Speakup/app/__init__.py:46]
2020-08-31 11:58:10,303 INFO: Microblog startup [in /Users/michellewong/Documents/Speakup/app/__init__.py:46]
2020-08-31 11:58:54,636 INFO: Microblog startup [in /Users/michellewong/Documents/Speakup/app/__init__.py:46]
2020-08-31 11:59:43,230 INFO: Microblog startup [in /Users/michellewong/Documents/Speakup/app/__init__.py:46]
2020-08-31 12:22:44,975 INFO: Microblog startup [in /Users/michellewong/Documents/Speakup/app/__init__.py:46]
2020-08-31 12:22:47,422 ERROR: Exception on /myrepresentative [GET] [in /Users/michellewong/Documents/Speakup/venv/lib/python3.7/site-packages/flask/app.py:1892]
Traceback (most recent call last):
  File "/Users/michellewong/Documents/Speakup/venv/lib/python3.7/site-packages/flask/app.py", line 2447, in wsgi_app
    response = self.full_dispatch_request()
  File "/Users/michellewong/Documents/Speakup/venv/lib/python3.7/site-packages/flask/app.py", line 1952, in full_dispatch_request
    rv = self.handle_user_exception(e)
  File "/Users/michellewong/Documents/Speakup/venv/lib/python3.7/site-packages/flask/app.py", line 1821, in handle_user_exception
    reraise(exc_type, exc_value, tb)
  File "/Users/michellewong/Documents/Speakup/venv/lib/python3.7/site-packages/flask/_compat.py", line 39, in reraise
    raise value
  File "/Users/michellewong/Documents/Speakup/venv/lib/python3.7/site-packages/flask/app.py", line 1950, in full_dispatch_request
    rv = self.dispatch_request()
  File "/Users/michellewong/Documents/Speakup/venv/lib/python3.7/site-packages/flask/app.py", line 1936, in dispatch_request
    return self.view_functions[rule.endpoint](**req.view_args)
  File "/Users/michellewong/Documents/Speakup/venv/lib/python3.7/site-packages/flask_login/utils.py", line 272, in decorated_view
    return func(*args, **kwargs)
  File "/Users/michellewong/Documents/Speakup/app/routes.py", line 170, in myrepresentative
    return render_template('yourrep.html', data = json_data, image = image )
  File "/Users/michellewong/Documents/Speakup/venv/lib/python3.7/site-packages/flask/templating.py", line 140, in render_template
    ctx.app,
  File "/Users/michellewong/Documents/Speakup/venv/lib/python3.7/site-packages/flask/templating.py", line 120, in _render
    rv = template.render(context)
  File "/Users/michellewong/Documents/Speakup/venv/lib/python3.7/site-packages/jinja2/environment.py", line 1090, in render
    self.environment.handle_exception()
  File "/Users/michellewong/Documents/Speakup/venv/lib/python3.7/site-packages/jinja2/environment.py", line 832, in handle_exception
    reraise(*rewrite_traceback_stack(source=source))
  File "/Users/michellewong/Documents/Speakup/venv/lib/python3.7/site-packages/jinja2/_compat.py", line 28, in reraise
    raise value.with_traceback(tb)
  File "/Users/michellewong/Documents/Speakup/app/templates/yourrep.html", line 1, in top-level template code
    {% extends "navbar.html" %}
  File "/Users/michellewong/Documents/Speakup/app/templates/navbar.html", line 51, in top-level template code
    {% block content %}{% endblock %}
  File "/Users/michellewong/Documents/Speakup/app/templates/yourrep.html", line 84, in block "content"
    {{data.name.first}} {{data.name.last}}
  File "/Users/michellewong/Documents/Speakup/venv/lib/python3.7/site-packages/jinja2/environment.py", line 471, in getattr
    return getattr(obj, attribute)
jinja2.exceptions.UndefinedError: 'dict object' has no attribute 'name'
2020-08-31 12:23:06,417 INFO: Microblog startup [in /Users/michellewong/Documents/Speakup/app/__init__.py:46]
2020-08-31 12:24:26,012 INFO: Microblog startup [in /Users/michellewong/Documents/Speakup/app/__init__.py:46]
2020-09-01 09:48:23,246 INFO: Microblog startup [in /Users/michellewong/Documents/Speakup/app/__init__.py:46]
