2020-09-10 14:56:01,033 ERROR: Exception on /index [GET] [in /Users/michellewong/Documents/Speakup/venv/lib/python3.7/site-packages/flask/app.py:1892]
Traceback (most recent call last):
  File "/Users/michellewong/Documents/Speakup/venv/lib/python3.7/site-packages/flask/app.py", line 2447, in wsgi_app
    response = self.full_dispatch_request()
  File "/Users/michellewong/Documents/Speakup/venv/lib/python3.7/site-packages/flask/app.py", line 1952, in full_dispatch_request
    rv = self.handle_user_exception(e)
  File "/Users/michellewong/Documents/Speakup/venv/lib/python3.7/site-packages/flask/app.py", line 1821, in handle_user_exception
    reraise(exc_type, exc_value, tb)
  File "/Users/michellewong/Documents/Speakup/venv/lib/python3.7/site-packages/flask/_compat.py", line 39, in reraise
    raise value
  File "/Users/michellewong/Documents/Speakup/venv/lib/python3.7/site-packages/flask/app.py", line 1948, in full_dispatch_request
    rv = self.preprocess_request()
  File "/Users/michellewong/Documents/Speakup/venv/lib/python3.7/site-packages/flask/app.py", line 2242, in preprocess_request
    rv = func()
  File "/Users/michellewong/Documents/Speakup/app/main/routes.py", line 25, in before_request
    current_user.launch_task('rebuild_hansard', 'Updating hansard',description = datetime.now().date().strftime('%m/%d/%Y'))
TypeError: launch_task() got multiple values for argument 'description'
2020-09-10 15:06:51,588 INFO: Microblog startup [in /Users/michellewong/Documents/Speakup/app/__init__.py:88]
2020-09-10 15:08:15,957 INFO: Microblog startup [in ./app/__init__.py:88]
2020-09-10 15:08:16,754 INFO: Microblog startup [in ./app/__init__.py:88]
2020-09-10 15:08:17,512 INFO: Microblog startup [in ./app/__init__.py:88]
2020-09-10 15:08:18,269 INFO: Microblog startup [in ./app/__init__.py:88]
2020-09-10 15:11:16,546 INFO: Microblog startup [in /Users/michellewong/Documents/Speakup/app/__init__.py:88]
2020-09-10 15:12:50,756 INFO: Microblog startup [in /Users/michellewong/Documents/Speakup/app/__init__.py:88]
2020-09-10 15:12:57,194 INFO: Microblog startup [in /Users/michellewong/Documents/Speakup/app/__init__.py:88]
2020-09-10 15:13:47,312 INFO: Microblog startup [in ./app/__init__.py:88]
2020-09-10 15:14:43,912 INFO: Microblog startup [in /Users/michellewong/Documents/Speakup/app/__init__.py:88]
2020-09-10 15:14:56,252 INFO: Microblog startup [in ./app/__init__.py:88]
2020-09-10 15:14:57,144 INFO: Microblog startup [in ./app/__init__.py:88]
2020-09-10 15:14:58,113 INFO: Microblog startup [in ./app/__init__.py:88]
2020-09-10 15:14:59,162 INFO: Microblog startup [in ./app/__init__.py:88]
2020-09-10 15:15:00,024 INFO: Microblog startup [in ./app/__init__.py:88]
2020-09-10 15:15:00,876 INFO: Microblog startup [in ./app/__init__.py:88]
2020-09-10 15:15:01,746 INFO: Microblog startup [in ./app/__init__.py:88]
2020-09-10 15:15:13,605 INFO: Microblog startup [in /Users/michellewong/Documents/Speakup/app/__init__.py:88]
2020-09-10 15:15:32,188 INFO: Microblog startup [in /Users/michellewong/Documents/Speakup/app/__init__.py:88]
2020-09-10 15:15:38,401 INFO: Microblog startup [in /Users/michellewong/Documents/Speakup/app/__init__.py:88]
2020-09-10 15:15:55,708 INFO: Microblog startup [in /Users/michellewong/Documents/Speakup/app/__init__.py:88]
2020-09-10 15:16:03,870 INFO: Microblog startup [in /Users/michellewong/Documents/Speakup/app/__init__.py:88]
2020-09-10 15:16:04,907 ERROR: Exception on /notifications [GET] [in /Users/michellewong/Documents/Speakup/venv/lib/python3.7/site-packages/flask/app.py:1892]
Traceback (most recent call last):
  File "/Users/michellewong/Documents/Speakup/venv/lib/python3.7/site-packages/sqlalchemy/engine/base.py", line 1277, in _execute_context
    cursor, statement, parameters, context
  File "/Users/michellewong/Documents/Speakup/venv/lib/python3.7/site-packages/sqlalchemy/engine/default.py", line 593, in do_execute
    cursor.execute(statement, parameters)
sqlite3.OperationalError: no such table: user

The above exception was the direct cause of the following exception:

Traceback (most recent call last):
  File "/Users/michellewong/Documents/Speakup/venv/lib/python3.7/site-packages/flask/app.py", line 2447, in wsgi_app
    response = self.full_dispatch_request()
  File "/Users/michellewong/Documents/Speakup/venv/lib/python3.7/site-packages/flask/app.py", line 1952, in full_dispatch_request
    rv = self.handle_user_exception(e)
  File "/Users/michellewong/Documents/Speakup/venv/lib/python3.7/site-packages/flask/app.py", line 1821, in handle_user_exception
    reraise(exc_type, exc_value, tb)
  File "/Users/michellewong/Documents/Speakup/venv/lib/python3.7/site-packages/flask/_compat.py", line 39, in reraise
    raise value
  File "/Users/michellewong/Documents/Speakup/venv/lib/python3.7/site-packages/flask/app.py", line 1948, in full_dispatch_request
    rv = self.preprocess_request()
  File "/Users/michellewong/Documents/Speakup/venv/lib/python3.7/site-packages/flask/app.py", line 2242, in preprocess_request
    rv = func()
  File "/Users/michellewong/Documents/Speakup/app/main/routes.py", line 20, in before_request
    if current_user.is_authenticated:
  File "/Users/michellewong/Documents/Speakup/venv/lib/python3.7/site-packages/werkzeug/local.py", line 347, in __getattr__
    return getattr(self._get_current_object(), name)
  File "/Users/michellewong/Documents/Speakup/venv/lib/python3.7/site-packages/werkzeug/local.py", line 306, in _get_current_object
    return self.__local()
  File "/Users/michellewong/Documents/Speakup/venv/lib/python3.7/site-packages/flask_login/utils.py", line 26, in <lambda>
    current_user = LocalProxy(lambda: _get_user())
  File "/Users/michellewong/Documents/Speakup/venv/lib/python3.7/site-packages/flask_login/utils.py", line 346, in _get_user
    current_app.login_manager._load_user()
  File "/Users/michellewong/Documents/Speakup/venv/lib/python3.7/site-packages/flask_login/login_manager.py", line 318, in _load_user
    user = self._user_callback(user_id)
  File "/Users/michellewong/Documents/Speakup/app/models.py", line 199, in load_user
    return User.query.get(int(id))
  File "/Users/michellewong/Documents/Speakup/venv/lib/python3.7/site-packages/sqlalchemy/orm/query.py", line 1018, in get
    return self._get_impl(ident, loading.load_on_pk_identity)
  File "/Users/michellewong/Documents/Speakup/venv/lib/python3.7/site-packages/sqlalchemy/orm/query.py", line 1135, in _get_impl
    return db_load_fn(self, primary_key_identity)
  File "/Users/michellewong/Documents/Speakup/venv/lib/python3.7/site-packages/sqlalchemy/orm/loading.py", line 286, in load_on_pk_identity
    return q.one()
  File "/Users/michellewong/Documents/Speakup/venv/lib/python3.7/site-packages/sqlalchemy/orm/query.py", line 3463, in one
    ret = self.one_or_none()
  File "/Users/michellewong/Documents/Speakup/venv/lib/python3.7/site-packages/sqlalchemy/orm/query.py", line 3432, in one_or_none
    ret = list(self)
  File "/Users/michellewong/Documents/Speakup/venv/lib/python3.7/site-packages/sqlalchemy/orm/query.py", line 3508, in __iter__
    return self._execute_and_instances(context)
  File "/Users/michellewong/Documents/Speakup/venv/lib/python3.7/site-packages/sqlalchemy/orm/query.py", line 3533, in _execute_and_instances
    result = conn.execute(querycontext.statement, self._params)
  File "/Users/michellewong/Documents/Speakup/venv/lib/python3.7/site-packages/sqlalchemy/engine/base.py", line 1011, in execute
    return meth(self, multiparams, params)
  File "/Users/michellewong/Documents/Speakup/venv/lib/python3.7/site-packages/sqlalchemy/sql/elements.py", line 298, in _execute_on_connection
    return connection._execute_clauseelement(self, multiparams, params)
  File "/Users/michellewong/Documents/Speakup/venv/lib/python3.7/site-packages/sqlalchemy/engine/base.py", line 1130, in _execute_clauseelement
    distilled_params,
  File "/Users/michellewong/Documents/Speakup/venv/lib/python3.7/site-packages/sqlalchemy/engine/base.py", line 1317, in _execute_context
    e, statement, parameters, cursor, context
  File "/Users/michellewong/Documents/Speakup/venv/lib/python3.7/site-packages/sqlalchemy/engine/base.py", line 1511, in _handle_dbapi_exception
    sqlalchemy_exception, with_traceback=exc_info[2], from_=e
  File "/Users/michellewong/Documents/Speakup/venv/lib/python3.7/site-packages/sqlalchemy/util/compat.py", line 182, in raise_
    raise exception
  File "/Users/michellewong/Documents/Speakup/venv/lib/python3.7/site-packages/sqlalchemy/engine/base.py", line 1277, in _execute_context
    cursor, statement, parameters, context
  File "/Users/michellewong/Documents/Speakup/venv/lib/python3.7/site-packages/sqlalchemy/engine/default.py", line 593, in do_execute
    cursor.execute(statement, parameters)
sqlalchemy.exc.OperationalError: (sqlite3.OperationalError) no such table: user
[SQL: SELECT user.id AS user_id, user.username AS user_username, user.email AS user_email, user.password_hash AS user_password_hash, user.about_me AS user_about_me, user.representative AS user_representative, user.constituency AS user_constituency, user.postcode AS user_postcode, user.last_seen AS user_last_seen, user.last_message_read_time AS user_last_message_read_time 
FROM user 
WHERE user.id = ?]
[parameters: (1,)]
(Background on this error at: http://sqlalche.me/e/13/e3q8)
