2020-09-10 18:49:45,437 ERROR: Exception on / [GET] [in /Users/michellewong/Documents/Speakup/venv/lib/python3.7/site-packages/flask/app.py:1892]
Traceback (most recent call last):
  File "/Users/michellewong/Documents/Speakup/venv/lib/python3.7/site-packages/sqlalchemy/engine/base.py", line 2338, in _wrap_pool_connect
    return fn()
  File "/Users/michellewong/Documents/Speakup/venv/lib/python3.7/site-packages/sqlalchemy/pool/base.py", line 364, in connect
    return _ConnectionFairy._checkout(self)
  File "/Users/michellewong/Documents/Speakup/venv/lib/python3.7/site-packages/sqlalchemy/pool/base.py", line 778, in _checkout
    fairy = _ConnectionRecord.checkout(pool)
  File "/Users/michellewong/Documents/Speakup/venv/lib/python3.7/site-packages/sqlalchemy/pool/base.py", line 495, in checkout
    rec = pool._do_get()
  File "/Users/michellewong/Documents/Speakup/venv/lib/python3.7/site-packages/sqlalchemy/pool/impl.py", line 140, in _do_get
    self._dec_overflow()
  File "/Users/michellewong/Documents/Speakup/venv/lib/python3.7/site-packages/sqlalchemy/util/langhelpers.py", line 69, in __exit__
    exc_value, with_traceback=exc_tb,
  File "/Users/michellewong/Documents/Speakup/venv/lib/python3.7/site-packages/sqlalchemy/util/compat.py", line 182, in raise_
    raise exception
  File "/Users/michellewong/Documents/Speakup/venv/lib/python3.7/site-packages/sqlalchemy/pool/impl.py", line 137, in _do_get
    return self._create_connection()
  File "/Users/michellewong/Documents/Speakup/venv/lib/python3.7/site-packages/sqlalchemy/pool/base.py", line 309, in _create_connection
    return _ConnectionRecord(self)
  File "/Users/michellewong/Documents/Speakup/venv/lib/python3.7/site-packages/sqlalchemy/pool/base.py", line 440, in __init__
    self.__connect(first_connect_check=True)
  File "/Users/michellewong/Documents/Speakup/venv/lib/python3.7/site-packages/sqlalchemy/pool/base.py", line 661, in __connect
    pool.logger.debug("Error on connect(): %s", e)
  File "/Users/michellewong/Documents/Speakup/venv/lib/python3.7/site-packages/sqlalchemy/util/langhelpers.py", line 69, in __exit__
    exc_value, with_traceback=exc_tb,
  File "/Users/michellewong/Documents/Speakup/venv/lib/python3.7/site-packages/sqlalchemy/util/compat.py", line 182, in raise_
    raise exception
  File "/Users/michellewong/Documents/Speakup/venv/lib/python3.7/site-packages/sqlalchemy/pool/base.py", line 656, in __connect
    connection = pool._invoke_creator(self)
  File "/Users/michellewong/Documents/Speakup/venv/lib/python3.7/site-packages/sqlalchemy/engine/strategies.py", line 114, in connect
    return dialect.connect(*cargs, **cparams)
  File "/Users/michellewong/Documents/Speakup/venv/lib/python3.7/site-packages/sqlalchemy/engine/default.py", line 493, in connect
    return self.dbapi.connect(*cargs, **cparams)
pyodbc.Error: ('01000', "[01000] [unixODBC][Driver Manager]Can't open lib '/usr/local/lib/libmsodbcsql.13.dylib' : file not found (0) (SQLDriverConnect)")

The above exception was the direct cause of the following exception:

Traceback (most recent call last):
  File "/Users/michellewong/Documents/Speakup/venv/lib/python3.7/site-packages/flask/app.py", line 2447, in wsgi_app
    response = self.full_dispatch_request()
  File "/Users/michellewong/Documents/Speakup/venv/lib/python3.7/site-packages/flask/app.py", line 1952, in full_dispatch_request
    rv = self.handle_user_exception(e)
  File "/Users/michellewong/Documents/Speakup/venv/lib/python3.7/site-packages/flask/app.py", line 1821, in handle_user_exception
    reraise(exc_type, exc_value, tb)
  File "/Users/michellewong/Documents/Speakup/venv/lib/python3.7/site-packages/flask/_compat.py", line 39, in reraise
    raise value
  File "/Users/michellewong/Documents/Speakup/venv/lib/python3.7/site-packages/flask/app.py", line 1948, in full_dispatch_request
    rv = self.preprocess_request()
  File "/Users/michellewong/Documents/Speakup/venv/lib/python3.7/site-packages/flask/app.py", line 2242, in preprocess_request
    rv = func()
  File "/Users/michellewong/Documents/Speakup/app/main/routes.py", line 20, in before_request
    if current_user.is_authenticated:
  File "/Users/michellewong/Documents/Speakup/venv/lib/python3.7/site-packages/werkzeug/local.py", line 347, in __getattr__
    return getattr(self._get_current_object(), name)
  File "/Users/michellewong/Documents/Speakup/venv/lib/python3.7/site-packages/werkzeug/local.py", line 306, in _get_current_object
    return self.__local()
  File "/Users/michellewong/Documents/Speakup/venv/lib/python3.7/site-packages/flask_login/utils.py", line 26, in <lambda>
    current_user = LocalProxy(lambda: _get_user())
  File "/Users/michellewong/Documents/Speakup/venv/lib/python3.7/site-packages/flask_login/utils.py", line 346, in _get_user
    current_app.login_manager._load_user()
  File "/Users/michellewong/Documents/Speakup/venv/lib/python3.7/site-packages/flask_login/login_manager.py", line 318, in _load_user
    user = self._user_callback(user_id)
  File "/Users/michellewong/Documents/Speakup/app/models.py", line 199, in load_user
    return User.query.get(int(id))
  File "/Users/michellewong/Documents/Speakup/venv/lib/python3.7/site-packages/sqlalchemy/orm/query.py", line 1018, in get
    return self._get_impl(ident, loading.load_on_pk_identity)
  File "/Users/michellewong/Documents/Speakup/venv/lib/python3.7/site-packages/sqlalchemy/orm/query.py", line 1135, in _get_impl
    return db_load_fn(self, primary_key_identity)
  File "/Users/michellewong/Documents/Speakup/venv/lib/python3.7/site-packages/sqlalchemy/orm/loading.py", line 286, in load_on_pk_identity
    return q.one()
  File "/Users/michellewong/Documents/Speakup/venv/lib/python3.7/site-packages/sqlalchemy/orm/query.py", line 3463, in one
    ret = self.one_or_none()
  File "/Users/michellewong/Documents/Speakup/venv/lib/python3.7/site-packages/sqlalchemy/orm/query.py", line 3432, in one_or_none
    ret = list(self)
  File "/Users/michellewong/Documents/Speakup/venv/lib/python3.7/site-packages/sqlalchemy/orm/query.py", line 3508, in __iter__
    return self._execute_and_instances(context)
  File "/Users/michellewong/Documents/Speakup/venv/lib/python3.7/site-packages/sqlalchemy/orm/query.py", line 3530, in _execute_and_instances
    querycontext, self._connection_from_session, close_with_result=True
  File "/Users/michellewong/Documents/Speakup/venv/lib/python3.7/site-packages/sqlalchemy/orm/query.py", line 3545, in _get_bind_args
    mapper=self._bind_mapper(), clause=querycontext.statement, **kw
  File "/Users/michellewong/Documents/Speakup/venv/lib/python3.7/site-packages/sqlalchemy/orm/query.py", line 3523, in _connection_from_session
    conn = self.session.connection(**kw)
  File "/Users/michellewong/Documents/Speakup/venv/lib/python3.7/site-packages/sqlalchemy/orm/session.py", line 1141, in connection
    execution_options=execution_options,
  File "/Users/michellewong/Documents/Speakup/venv/lib/python3.7/site-packages/sqlalchemy/orm/session.py", line 1147, in _connection_for_bind
    engine, execution_options
  File "/Users/michellewong/Documents/Speakup/venv/lib/python3.7/site-packages/sqlalchemy/orm/session.py", line 433, in _connection_for_bind
    conn = bind._contextual_connect()
  File "/Users/michellewong/Documents/Speakup/venv/lib/python3.7/site-packages/sqlalchemy/engine/base.py", line 2304, in _contextual_connect
    self._wrap_pool_connect(self.pool.connect, None),
  File "/Users/michellewong/Documents/Speakup/venv/lib/python3.7/site-packages/sqlalchemy/engine/base.py", line 2342, in _wrap_pool_connect
    e, dialect, self
  File "/Users/michellewong/Documents/Speakup/venv/lib/python3.7/site-packages/sqlalchemy/engine/base.py", line 1584, in _handle_dbapi_exception_noconnection
    sqlalchemy_exception, with_traceback=exc_info[2], from_=e
  File "/Users/michellewong/Documents/Speakup/venv/lib/python3.7/site-packages/sqlalchemy/util/compat.py", line 182, in raise_
    raise exception
  File "/Users/michellewong/Documents/Speakup/venv/lib/python3.7/site-packages/sqlalchemy/engine/base.py", line 2338, in _wrap_pool_connect
    return fn()
  File "/Users/michellewong/Documents/Speakup/venv/lib/python3.7/site-packages/sqlalchemy/pool/base.py", line 364, in connect
    return _ConnectionFairy._checkout(self)
  File "/Users/michellewong/Documents/Speakup/venv/lib/python3.7/site-packages/sqlalchemy/pool/base.py", line 778, in _checkout
    fairy = _ConnectionRecord.checkout(pool)
  File "/Users/michellewong/Documents/Speakup/venv/lib/python3.7/site-packages/sqlalchemy/pool/base.py", line 495, in checkout
    rec = pool._do_get()
  File "/Users/michellewong/Documents/Speakup/venv/lib/python3.7/site-packages/sqlalchemy/pool/impl.py", line 140, in _do_get
    self._dec_overflow()
  File "/Users/michellewong/Documents/Speakup/venv/lib/python3.7/site-packages/sqlalchemy/util/langhelpers.py", line 69, in __exit__
    exc_value, with_traceback=exc_tb,
  File "/Users/michellewong/Documents/Speakup/venv/lib/python3.7/site-packages/sqlalchemy/util/compat.py", line 182, in raise_
    raise exception
  File "/Users/michellewong/Documents/Speakup/venv/lib/python3.7/site-packages/sqlalchemy/pool/impl.py", line 137, in _do_get
    return self._create_connection()
  File "/Users/michellewong/Documents/Speakup/venv/lib/python3.7/site-packages/sqlalchemy/pool/base.py", line 309, in _create_connection
    return _ConnectionRecord(self)
  File "/Users/michellewong/Documents/Speakup/venv/lib/python3.7/site-packages/sqlalchemy/pool/base.py", line 440, in __init__
    self.__connect(first_connect_check=True)
  File "/Users/michellewong/Documents/Speakup/venv/lib/python3.7/site-packages/sqlalchemy/pool/base.py", line 661, in __connect
    pool.logger.debug("Error on connect(): %s", e)
  File "/Users/michellewong/Documents/Speakup/venv/lib/python3.7/site-packages/sqlalchemy/util/langhelpers.py", line 69, in __exit__
    exc_value, with_traceback=exc_tb,
  File "/Users/michellewong/Documents/Speakup/venv/lib/python3.7/site-packages/sqlalchemy/util/compat.py", line 182, in raise_
    raise exception
  File "/Users/michellewong/Documents/Speakup/venv/lib/python3.7/site-packages/sqlalchemy/pool/base.py", line 656, in __connect
    connection = pool._invoke_creator(self)
  File "/Users/michellewong/Documents/Speakup/venv/lib/python3.7/site-packages/sqlalchemy/engine/strategies.py", line 114, in connect
    return dialect.connect(*cargs, **cparams)
  File "/Users/michellewong/Documents/Speakup/venv/lib/python3.7/site-packages/sqlalchemy/engine/default.py", line 493, in connect
    return self.dbapi.connect(*cargs, **cparams)
sqlalchemy.exc.DBAPIError: (pyodbc.Error) ('01000', "[01000] [unixODBC][Driver Manager]Can't open lib '/usr/local/lib/libmsodbcsql.13.dylib' : file not found (0) (SQLDriverConnect)")
(Background on this error at: http://sqlalche.me/e/13/dbapi)
