2020-09-05 10:27:27,874 INFO: Microblog startup [in /Users/michellewong/Documents/Speakup/app/__init__.py:50]
2020-09-05 10:28:56,087 INFO: Microblog startup [in /Users/michellewong/Documents/Speakup/app/__init__.py:50]
2020-09-05 10:32:13,601 INFO: Microblog startup [in /Users/michellewong/Documents/Speakup/app/__init__.py:50]
2020-09-05 10:33:39,270 INFO: Microblog startup [in /Users/michellewong/Documents/Speakup/app/__init__.py:50]
2020-09-05 10:53:52,952 INFO: Microblog startup [in /Users/michellewong/Documents/Speakup/app/__init__.py:50]
2020-09-05 10:55:19,383 INFO: Microblog startup [in /Users/michellewong/Documents/Speakup/app/__init__.py:50]
2020-09-05 10:56:42,472 INFO: Microblog startup [in /Users/michellewong/Documents/Speakup/app/__init__.py:50]
2020-09-05 10:57:17,502 INFO: Microblog startup [in /Users/michellewong/Documents/Speakup/app/__init__.py:50]
2020-09-05 11:01:32,922 INFO: Microblog startup [in /Users/michellewong/Documents/Speakup/app/__init__.py:50]
2020-09-05 11:19:55,105 INFO: Microblog startup [in /Users/michellewong/Documents/Speakup/app/__init__.py:50]
2020-09-05 11:20:13,065 INFO: Microblog startup [in /Users/michellewong/Documents/Speakup/app/__init__.py:50]
2020-09-05 11:20:32,352 INFO: Microblog startup [in /Users/michellewong/Documents/Speakup/app/__init__.py:50]
2020-09-05 11:20:41,205 ERROR: Exception on /hansard/2020-08-31 [GET] [in /Users/michellewong/Documents/Speakup/venv/lib/python3.7/site-packages/flask/app.py:1892]
Traceback (most recent call last):
  File "/Users/michellewong/Documents/Speakup/venv/lib/python3.7/site-packages/flask/app.py", line 2447, in wsgi_app
    response = self.full_dispatch_request()
  File "/Users/michellewong/Documents/Speakup/venv/lib/python3.7/site-packages/flask/app.py", line 1952, in full_dispatch_request
    rv = self.handle_user_exception(e)
  File "/Users/michellewong/Documents/Speakup/venv/lib/python3.7/site-packages/flask/app.py", line 1821, in handle_user_exception
    reraise(exc_type, exc_value, tb)
  File "/Users/michellewong/Documents/Speakup/venv/lib/python3.7/site-packages/flask/_compat.py", line 39, in reraise
    raise value
  File "/Users/michellewong/Documents/Speakup/venv/lib/python3.7/site-packages/flask/app.py", line 1950, in full_dispatch_request
    rv = self.dispatch_request()
  File "/Users/michellewong/Documents/Speakup/venv/lib/python3.7/site-packages/flask/app.py", line 1936, in dispatch_request
    return self.view_functions[rule.endpoint](**req.view_args)
  File "/Users/michellewong/Documents/Speakup/venv/lib/python3.7/site-packages/flask_login/utils.py", line 272, in decorated_view
    return func(*args, **kwargs)
  File "/Users/michellewong/Documents/Speakup/app/routes.py", line 192, in hansard
    form2 = DateForm()
NameError: name 'DateForm' is not defined
2020-09-05 11:21:09,689 INFO: Microblog startup [in /Users/michellewong/Documents/Speakup/app/__init__.py:50]
2020-09-05 11:21:11,767 ERROR: Exception on /hansard/2020-08-31 [GET] [in /Users/michellewong/Documents/Speakup/venv/lib/python3.7/site-packages/flask/app.py:1892]
Traceback (most recent call last):
  File "/Users/michellewong/Documents/Speakup/venv/lib/python3.7/site-packages/flask/app.py", line 2447, in wsgi_app
    response = self.full_dispatch_request()
  File "/Users/michellewong/Documents/Speakup/venv/lib/python3.7/site-packages/flask/app.py", line 1952, in full_dispatch_request
    rv = self.handle_user_exception(e)
  File "/Users/michellewong/Documents/Speakup/venv/lib/python3.7/site-packages/flask/app.py", line 1821, in handle_user_exception
    reraise(exc_type, exc_value, tb)
  File "/Users/michellewong/Documents/Speakup/venv/lib/python3.7/site-packages/flask/_compat.py", line 39, in reraise
    raise value
  File "/Users/michellewong/Documents/Speakup/venv/lib/python3.7/site-packages/flask/app.py", line 1950, in full_dispatch_request
    rv = self.dispatch_request()
  File "/Users/michellewong/Documents/Speakup/venv/lib/python3.7/site-packages/flask/app.py", line 1936, in dispatch_request
    return self.view_functions[rule.endpoint](**req.view_args)
  File "/Users/michellewong/Documents/Speakup/venv/lib/python3.7/site-packages/flask_login/utils.py", line 272, in decorated_view
    return func(*args, **kwargs)
  File "/Users/michellewong/Documents/Speakup/app/routes.py", line 193, in hansard
    if form.validate_on_submit():
NameError: name 'form' is not defined
2020-09-05 11:21:40,858 ERROR: Exception on /hansard/2020-08-31 [GET] [in /Users/michellewong/Documents/Speakup/venv/lib/python3.7/site-packages/flask/app.py:1892]
Traceback (most recent call last):
  File "/Users/michellewong/Documents/Speakup/venv/lib/python3.7/site-packages/flask/app.py", line 2447, in wsgi_app
    response = self.full_dispatch_request()
  File "/Users/michellewong/Documents/Speakup/venv/lib/python3.7/site-packages/flask/app.py", line 1952, in full_dispatch_request
    rv = self.handle_user_exception(e)
  File "/Users/michellewong/Documents/Speakup/venv/lib/python3.7/site-packages/flask/app.py", line 1821, in handle_user_exception
    reraise(exc_type, exc_value, tb)
  File "/Users/michellewong/Documents/Speakup/venv/lib/python3.7/site-packages/flask/_compat.py", line 39, in reraise
    raise value
  File "/Users/michellewong/Documents/Speakup/venv/lib/python3.7/site-packages/flask/app.py", line 1950, in full_dispatch_request
    rv = self.dispatch_request()
  File "/Users/michellewong/Documents/Speakup/venv/lib/python3.7/site-packages/flask/app.py", line 1936, in dispatch_request
    return self.view_functions[rule.endpoint](**req.view_args)
  File "/Users/michellewong/Documents/Speakup/venv/lib/python3.7/site-packages/flask_login/utils.py", line 272, in decorated_view
    return func(*args, **kwargs)
  File "/Users/michellewong/Documents/Speakup/app/routes.py", line 193, in hansard
    if form1.validate_on_submit():
NameError: name 'form' is not defined
2020-09-05 11:21:45,971 INFO: Microblog startup [in /Users/michellewong/Documents/Speakup/app/__init__.py:50]
2020-09-05 11:21:48,254 ERROR: Exception on /hansard/2020-08-31 [GET] [in /Users/michellewong/Documents/Speakup/venv/lib/python3.7/site-packages/flask/app.py:1892]
Traceback (most recent call last):
  File "/Users/michellewong/Documents/Speakup/venv/lib/python3.7/site-packages/flask/app.py", line 2447, in wsgi_app
    response = self.full_dispatch_request()
  File "/Users/michellewong/Documents/Speakup/venv/lib/python3.7/site-packages/flask/app.py", line 1952, in full_dispatch_request
    rv = self.handle_user_exception(e)
  File "/Users/michellewong/Documents/Speakup/venv/lib/python3.7/site-packages/flask/app.py", line 1821, in handle_user_exception
    reraise(exc_type, exc_value, tb)
  File "/Users/michellewong/Documents/Speakup/venv/lib/python3.7/site-packages/flask/_compat.py", line 39, in reraise
    raise value
  File "/Users/michellewong/Documents/Speakup/venv/lib/python3.7/site-packages/flask/app.py", line 1950, in full_dispatch_request
    rv = self.dispatch_request()
  File "/Users/michellewong/Documents/Speakup/venv/lib/python3.7/site-packages/flask/app.py", line 1936, in dispatch_request
    return self.view_functions[rule.endpoint](**req.view_args)
  File "/Users/michellewong/Documents/Speakup/venv/lib/python3.7/site-packages/flask_login/utils.py", line 272, in decorated_view
    return func(*args, **kwargs)
  File "/Users/michellewong/Documents/Speakup/app/routes.py", line 202, in hansard
    return render_template('hansard.html',data = hansard, dates = dates, form1 = form1, form2=form2)
  File "/Users/michellewong/Documents/Speakup/venv/lib/python3.7/site-packages/flask/templating.py", line 140, in render_template
    ctx.app,
  File "/Users/michellewong/Documents/Speakup/venv/lib/python3.7/site-packages/flask/templating.py", line 120, in _render
    rv = template.render(context)
  File "/Users/michellewong/Documents/Speakup/venv/lib/python3.7/site-packages/jinja2/environment.py", line 1090, in render
    self.environment.handle_exception()
  File "/Users/michellewong/Documents/Speakup/venv/lib/python3.7/site-packages/jinja2/environment.py", line 832, in handle_exception
    reraise(*rewrite_traceback_stack(source=source))
  File "/Users/michellewong/Documents/Speakup/venv/lib/python3.7/site-packages/jinja2/_compat.py", line 28, in reraise
    raise value.with_traceback(tb)
  File "/Users/michellewong/Documents/Speakup/app/templates/hansard.html", line 1, in top-level template code
    {% extends "navbar.html" %}
  File "/Users/michellewong/Documents/Speakup/app/templates/navbar.html", line 52, in top-level template code
    {% block content %}{% endblock %}
  File "/Users/michellewong/Documents/Speakup/app/templates/hansard.html", line 178, in block "content"
    {% for error in form2.post.errors %}
  File "/Users/michellewong/Documents/Speakup/venv/lib/python3.7/site-packages/jinja2/environment.py", line 471, in getattr
    return getattr(obj, attribute)
jinja2.exceptions.UndefinedError: 'app.forms.Dateform object' has no attribute 'post'
2020-09-05 11:23:28,399 INFO: Microblog startup [in /Users/michellewong/Documents/Speakup/app/__init__.py:50]
