2020-09-10 20:26:50,366 ERROR: Exception on / [GET] [in /Users/michellewong/Documents/Speakup/venv/lib/python3.7/site-packages/flask/app.py:1892]
Traceback (most recent call last):
  File "/Users/michellewong/Documents/Speakup/venv/lib/python3.7/site-packages/sqlalchemy/engine/base.py", line 1277, in _execute_context
    cursor, statement, parameters, context
  File "/Users/michellewong/Documents/Speakup/venv/lib/python3.7/site-packages/sqlalchemy/engine/default.py", line 593, in do_execute
    cursor.execute(statement, parameters)
pyodbc.ProgrammingError: ('42000', "[42000] [Microsoft][ODBC Driver 17 for SQL Server][SQL Server]String or binary data would be truncated in table 'Speakupdata.dbo.minorheading', column 'body'. Truncated value: 'Offshore Petroleum and Greenhouse Gas Storage Amendment (Cross-boundary Greenhouse Gas Titles and Ot'. (2628) (SQLExecDirectW)")

The above exception was the direct cause of the following exception:

Traceback (most recent call last):
  File "/Users/michellewong/Documents/Speakup/venv/lib/python3.7/site-packages/flask/app.py", line 2447, in wsgi_app
    response = self.full_dispatch_request()
  File "/Users/michellewong/Documents/Speakup/venv/lib/python3.7/site-packages/flask/app.py", line 1952, in full_dispatch_request
    rv = self.handle_user_exception(e)
  File "/Users/michellewong/Documents/Speakup/venv/lib/python3.7/site-packages/flask/app.py", line 1821, in handle_user_exception
    reraise(exc_type, exc_value, tb)
  File "/Users/michellewong/Documents/Speakup/venv/lib/python3.7/site-packages/flask/_compat.py", line 39, in reraise
    raise value
  File "/Users/michellewong/Documents/Speakup/venv/lib/python3.7/site-packages/flask/app.py", line 1948, in full_dispatch_request
    rv = self.preprocess_request()
  File "/Users/michellewong/Documents/Speakup/venv/lib/python3.7/site-packages/flask/app.py", line 2242, in preprocess_request
    rv = func()
  File "/Users/michellewong/Documents/Speakup/app/main/routes.py", line 32, in before_request
    rebuild(date)
  File "/Users/michellewong/Documents/Speakup/app/rebuild.py", line 28, in rebuild
    if MajorHeading.query.filter_by(hansard=hansard,body=major_heading).first():
  File "/Users/michellewong/Documents/Speakup/venv/lib/python3.7/site-packages/sqlalchemy/orm/query.py", line 3402, in first
    ret = list(self[0:1])
  File "/Users/michellewong/Documents/Speakup/venv/lib/python3.7/site-packages/sqlalchemy/orm/query.py", line 3176, in __getitem__
    return list(res)
  File "/Users/michellewong/Documents/Speakup/venv/lib/python3.7/site-packages/sqlalchemy/orm/query.py", line 3507, in __iter__
    self.session._autoflush()
  File "/Users/michellewong/Documents/Speakup/venv/lib/python3.7/site-packages/sqlalchemy/orm/session.py", line 1628, in _autoflush
    util.raise_(e, with_traceback=sys.exc_info()[2])
  File "/Users/michellewong/Documents/Speakup/venv/lib/python3.7/site-packages/sqlalchemy/util/compat.py", line 182, in raise_
    raise exception
  File "/Users/michellewong/Documents/Speakup/venv/lib/python3.7/site-packages/sqlalchemy/orm/session.py", line 1617, in _autoflush
    self.flush()
  File "/Users/michellewong/Documents/Speakup/venv/lib/python3.7/site-packages/sqlalchemy/orm/session.py", line 2523, in flush
    self._flush(objects)
  File "/Users/michellewong/Documents/Speakup/venv/lib/python3.7/site-packages/sqlalchemy/orm/session.py", line 2664, in _flush
    transaction.rollback(_capture_exception=True)
  File "/Users/michellewong/Documents/Speakup/venv/lib/python3.7/site-packages/sqlalchemy/util/langhelpers.py", line 69, in __exit__
    exc_value, with_traceback=exc_tb,
  File "/Users/michellewong/Documents/Speakup/venv/lib/python3.7/site-packages/sqlalchemy/util/compat.py", line 182, in raise_
    raise exception
  File "/Users/michellewong/Documents/Speakup/venv/lib/python3.7/site-packages/sqlalchemy/orm/session.py", line 2624, in _flush
    flush_context.execute()
  File "/Users/michellewong/Documents/Speakup/venv/lib/python3.7/site-packages/sqlalchemy/orm/unitofwork.py", line 422, in execute
    rec.execute(self)
  File "/Users/michellewong/Documents/Speakup/venv/lib/python3.7/site-packages/sqlalchemy/orm/unitofwork.py", line 589, in execute
    uow,
  File "/Users/michellewong/Documents/Speakup/venv/lib/python3.7/site-packages/sqlalchemy/orm/persistence.py", line 245, in save_obj
    insert,
  File "/Users/michellewong/Documents/Speakup/venv/lib/python3.7/site-packages/sqlalchemy/orm/persistence.py", line 1136, in _emit_insert_statements
    statement, params
  File "/Users/michellewong/Documents/Speakup/venv/lib/python3.7/site-packages/sqlalchemy/engine/base.py", line 1011, in execute
    return meth(self, multiparams, params)
  File "/Users/michellewong/Documents/Speakup/venv/lib/python3.7/site-packages/sqlalchemy/sql/elements.py", line 298, in _execute_on_connection
    return connection._execute_clauseelement(self, multiparams, params)
  File "/Users/michellewong/Documents/Speakup/venv/lib/python3.7/site-packages/sqlalchemy/engine/base.py", line 1130, in _execute_clauseelement
    distilled_params,
  File "/Users/michellewong/Documents/Speakup/venv/lib/python3.7/site-packages/sqlalchemy/engine/base.py", line 1317, in _execute_context
    e, statement, parameters, cursor, context
  File "/Users/michellewong/Documents/Speakup/venv/lib/python3.7/site-packages/sqlalchemy/engine/base.py", line 1511, in _handle_dbapi_exception
    sqlalchemy_exception, with_traceback=exc_info[2], from_=e
  File "/Users/michellewong/Documents/Speakup/venv/lib/python3.7/site-packages/sqlalchemy/util/compat.py", line 182, in raise_
    raise exception
  File "/Users/michellewong/Documents/Speakup/venv/lib/python3.7/site-packages/sqlalchemy/engine/base.py", line 1277, in _execute_context
    cursor, statement, parameters, context
  File "/Users/michellewong/Documents/Speakup/venv/lib/python3.7/site-packages/sqlalchemy/engine/default.py", line 593, in do_execute
    cursor.execute(statement, parameters)
sqlalchemy.exc.ProgrammingError: (raised as a result of Query-invoked autoflush; consider using a session.no_autoflush block if this flush is occurring prematurely)
(pyodbc.ProgrammingError) ('42000', "[42000] [Microsoft][ODBC Driver 17 for SQL Server][SQL Server]String or binary data would be truncated in table 'Speakupdata.dbo.minorheading', column 'body'. Truncated value: 'Offshore Petroleum and Greenhouse Gas Storage Amendment (Cross-boundary Greenhouse Gas Titles and Ot'. (2628) (SQLExecDirectW)")
[SQL: INSERT INTO minorheading (order_id, major_id, body) OUTPUT inserted.id VALUES (?, ?, ?)]
[parameters: (48, 129, 'Offshore Petroleum and Greenhouse Gas Storage Amendment (Cross-boundary Greenhouse Gas Titles and Other Measures) Bill 2019, Offshore Petroleum and Greenhouse Gas Storage (Regulatory Levies) Amendment (Miscellaneous Measures) Bill 2019; Second Reading')]
(Background on this error at: http://sqlalche.me/e/13/f405)
2020-09-10 20:29:10,813 INFO: Microblog startup [in /Users/michellewong/Documents/Speakup/app/__init__.py:88]
2020-09-10 20:32:39,749 INFO: Microblog startup [in /Users/michellewong/Documents/Speakup/app/__init__.py:88]
2020-09-10 20:32:56,196 INFO: Microblog startup [in /Users/michellewong/Documents/Speakup/app/__init__.py:88]
2020-09-10 20:33:41,665 INFO: Microblog startup [in /Users/michellewong/Documents/Speakup/app/__init__.py:88]
2020-09-10 20:40:43,644 INFO: Microblog startup [in /Users/michellewong/Documents/Speakup/app/__init__.py:88]
2020-09-10 20:41:42,019 INFO: Microblog startup [in /Users/michellewong/Documents/Speakup/app/__init__.py:88]
2020-09-10 20:42:49,320 INFO: Microblog startup [in /Users/michellewong/Documents/Speakup/app/__init__.py:88]
2020-09-10 20:43:55,186 INFO: Microblog startup [in /Users/michellewong/Documents/Speakup/app/__init__.py:88]
